Workbook

Sheet Catálogo_SI
A1: ID_SI | B1: Nombre_oficial | C1: Sigla_Acronimo | D1: Tipo_o_patron_de_SI | E1: Categoria_institucional | F1: Descripcion_breve | G1: Procesos_institucionales_soportados | H1: Dependencia_duena_del_proceso | I1: Area_responsable_funcional | J1: Responsable_funcional | K1: Area_responsable_tecnica | L1: Responsable_tecnico | M1: Estado_del_SI | N1: Fecha_salida_produccion | O1: Version_actual | P1: Modelo_de_despliegue | Q1: Tipo_de_desarrollo_adquisicion | R1: Fabricante_o_proveedor_principal | S1: Tipo_de_licenciamiento | T1: Soporte_vigente_hasta | U1: Estado_ANS_terceros | V1: Marco_legal_mandatorio | W1: Objetivos_estrategicos_que_apoya | X1: Criticidad_operacional | Y1: Usuarios_activos | Z1: Cobertura_del_proceso | AA1: Clasificacion_de_la_informacion | AB1: Manejo_de_datos_personales | AC1: Interopera_con_entidades_externas | AD1: Numero_integraciones_activas | AE1: Numero_componentes_registrados | AF1: Valoracion_de_seguridad | AG1: Nivel_de_riesgo_residual | AH1: Backup_definido | AI1: Plan_de_continuidad | AJ1: Estado_documentacion_minima | AK1: Clasificacion_TIME | AL1: Tipo_intervencion_recomendada | AM1: Prioridad_intervencion | AN1: TCO_anual_total_COP | AO1: Ratio_TCO_por_usuario_COP | AP1: Ultima_revision_anual | AQ1: Proxima_revision_programada | AR1: Vigencia_del_registro
AD2: =IF($A2="","",COUNTIFS(Integraciones_Interfaces!$B:$B,$A2,Integraciones_Interfaces!$N:$N,"Activa")) | AE2: =IF($A2="","",COUNTIF(Componentes!$B:$B,$A2)) | AO2: =IF(OR($A2="",$AN2="",$Y2="",$Y2=0),"",ROUND($AN2/$Y2,0))
AD3: =IF($A3="","",COUNTIFS(Integraciones_Interfaces!$B:$B,$A3,Integraciones_Interfaces!$N:$N,"Activa")) | AE3: =IF($A3="","",COUNTIF(Componentes!$B:$B,$A3)) | AO3: =IF(OR($A3="",$AN3="",$Y3="",$Y3=0),"",ROUND($AN3/$Y3,0))
AD4: =IF($A4="","",COUNTIFS(Integraciones_Interfaces!$B:$B,$A4,Integraciones_Interfaces!$N:$N,"Activa")) | AE4: =IF($A4="","",COUNTIF(Componentes!$B:$B,$A4)) | AO4: =IF(OR($A4="",$AN4="",$Y4="",$Y4=0),"",ROUND($AN4/$Y4,0))
AD5: =IF($A5="","",COUNTIFS(Integraciones_Interfaces!$B:$B,$A5,Integraciones_Interfaces!$N:$N,"Activa")) | AE5: =IF($A5="","",COUNTIF(Componentes!$B:$B,$A5)) | AO5: =IF(OR($A5="",$AN5="",$Y5="",$Y5=0),"",ROUND($AN5/$Y5,0))
AD6: =IF($A6="","",COUNTIFS(Integraciones_Interfaces!$B:$B,$A6,Integraciones_Interfaces!$N:$N,"Activa")) | AE6: =IF($A6="","",COUNTIF(Componentes!$B:$B,$A6)) | AO6: =IF(OR($A6="",$AN6="",$Y6="",$Y6=0),"",ROUND($AN6/$Y6,0))
AD7: =IF($A7="","",COUNTIFS(Integraciones_Interfaces!$B:$B,$A7,Integraciones_Interfaces!$N:$N,"Activa")) | AE7: =IF($A7="","",COUNTIF(Componentes!$B:$B,$A7)) | AO7: =IF(OR($A7="",$AN7="",$Y7="",$Y7=0),"",ROUND($AN7/$Y7,0))
AD8: =IF($A8="","",COUNTIFS(Integraciones_Interfaces!$B:$B,$A8,Integraciones_Interfaces!$N:$N,"Activa")) | AE8: =IF($A8="","",COUNTIF(Componentes!$B:$B,$A8)) | AO8: =IF(OR($A8="",$AN8="",$Y8="",$Y8=0),"",ROUND($AN8/$Y8,0))
AD9: =IF($A9="","",COUNTIFS(Integraciones_Interfaces!$B:$B,$A9,Integraciones_Interfaces!$N:$N,"Activa")) | AE9: =IF($A9="","",COUNTIF(Componentes!$B:$B,$A9)) | AO9: =IF(OR($A9="",$AN9="",$Y9="",$Y9=0),"",ROUND($AN9/$Y9,0))
AD10: =IF($A10="","",COUNTIFS(Integraciones_Interfaces!$B:$B,$A10,Integraciones_Interfaces!$N:$N,"Activa")) | AE10: =IF($A10="","",COUNTIF(Componentes!$B:$B,$A10)) | AO10: =IF(OR($A10="",$AN10="",$Y10="",$Y10=0),"",ROUND($AN10/$Y10,0))
AD11: =IF($A11="","",COUNTIFS(Integraciones_Interfaces!$B:$B,$A11,Integraciones_Interfaces!$N:$N,"Activa")) | AE11: =IF($A11="","",COUNTIF(Componentes!$B:$B,$A11)) | AO11: =IF(OR($A11="",$AN11="",$Y11="",$Y11=0),"",ROUND($AN11/$Y11,0))
AD12: =IF($A12="","",COUNTIFS(Integraciones_Interfaces!$B:$B,$A12,Integraciones_Interfaces!$N:$N,"Activa")) | AE12: =IF($A12="","",COUNTIF(Componentes!$B:$B,$A12)) | AO12: =IF(OR($A12="",$AN12="",$Y12="",$Y12=0),"",ROUND($AN12/$Y12,0))
AD13: =IF($A13="","",COUNTIFS(Integraciones_Interfaces!$B:$B,$A13,Integraciones_Interfaces!$N:$N,"Activa")) | AE13: =IF($A13="","",COUNTIF(Componentes!$B:$B,$A13)) | AO13: =IF(OR($A13="",$AN13="",$Y13="",$Y13=0),"",ROUND($AN13/$Y13,0))
... AD501: =IF($A501="","",COUNTIFS(Integraciones_Interfaces!$B:$B,$A501,Integraciones_Interfaces!$N:$N,"Activa")) | AE501: =IF($A501="","",COUNTIF(Componentes!$B:$B,$A501)) | AO501: =IF(OR($A501="",$AN501="",$Y501="",$Y501=0),"",ROUND($AN501/$Y501,0))

Sheet Integraciones_Interfaces
A1: ID_Integracion | B1: ID_SI_Origen | C1: Nombre_SI_Origen | D1: ID_SI_Destino_o_Activo_Destino | E1: Nombre_Destino | F1: Tipo_de_registro | G1: Tipo_de_interfaz_o_mecanismo | H1: Proposito | I1: Direccion_del_flujo | J1: Entidad_externa_relacionada | K1: Criticidad | L1: Frecuencia | M1: Responsable_tecnico | N1: Estado | O1: Observaciones
C2: =IF($B2="","",IFERROR(VLOOKUP($B2,'Catálogo_SI'!$A:$B,2,FALSE),"ID no encontrado"))
C3: =IF($B3="","",IFERROR(VLOOKUP($B3,'Catálogo_SI'!$A:$B,2,FALSE),"ID no encontrado"))
C4: =IF($B4="","",IFERROR(VLOOKUP($B4,'Catálogo_SI'!$A:$B,2,FALSE),"ID no encontrado"))
C5: =IF($B5="","",IFERROR(VLOOKUP($B5,'Catálogo_SI'!$A:$B,2,FALSE),"ID no encontrado"))
C6: =IF($B6="","",IFERROR(VLOOKUP($B6,'Catálogo_SI'!$A:$B,2,FALSE),"ID no encontrado"))
C7: =IF($B7="","",IFERROR(VLOOKUP($B7,'Catálogo_SI'!$A:$B,2,FALSE),"ID no encontrado"))
C8: =IF($B8="","",IFERROR(VLOOKUP($B8,'Catálogo_SI'!$A:$B,2,FALSE),"ID no encontrado"))
C9: =IF($B9="","",IFERROR(VLOOKUP($B9,'Catálogo_SI'!$A:$B,2,FALSE),"ID no encontrado"))
C10: =IF($B10="","",IFERROR(VLOOKUP($B10,'Catálogo_SI'!$A:$B,2,FALSE),"ID no encontrado"))
C11: =IF($B11="","",IFERROR(VLOOKUP($B11,'Catálogo_SI'!$A:$B,2,FALSE),"ID no encontrado"))
C12: =IF($B12="","",IFERROR(VLOOKUP($B12,'Catálogo_SI'!$A:$B,2,FALSE),"ID no encontrado"))
C13: =IF($B13="","",IFERROR(VLOOKUP($B13,'Catálogo_SI'!$A:$B,2,FALSE),"ID no encontrado"))
... C501: =IF($B501="","",IFERROR(VLOOKUP($B501,'Catálogo_SI'!$A:$B,2,FALSE),"ID no encontrado"))

Sheet Componentes
A1: ID_Componente | B1: ID_SI_Padre | C1: Nombre_Componente | D1: Tipo_de_Componente | E1: Funcion | F1: Compartido_con_otro_SI | G1: Estado | H1: Version | I1: Modelo_de_despliegue | J1: Tecnologia_principal | K1: Base_de_datos_asociada | L1: Proveedor_o_Fabricante | M1: Soporte_vigente_hasta | N1: Criticidad | O1: Observaciones

Sheet Diccionario
A1: Hoja | B1: Campo | C1: Definición | D1: Fuente | E1: Obligatoriedad | F1: Responsable del dato | G1: Tipo de dato | H1: Vocabulario / regla de validación | I1: Fórmula (si aplica) | J1: Origen (Catálogo / Ficha / Calculado)
A2: Catálogo_SI | B2: ID_SI | C2: Código único del SI. | D2: Institucional | E2: Obligatorio | F2: OTIC | G2: Texto | H2: Patrón SI-#### definido por OTIC | J2: Catálogo
A3: Catálogo_SI | B3: Nombre_oficial | C3: Nombre institucional vigente del SI. | D3: Institucional | E3: Obligatorio | F3: Responsable funcional | G3: Texto | H3: No aplica | J3: Catálogo
A4: Catálogo_SI | B4: Sigla_Acronimo | C4: Sigla o acrónimo usado oficialmente. | D4: Institucional | E4: Recomendado | F4: Responsable funcional | G4: Texto | H4: No aplica | J4: Catálogo
A5: Catálogo_SI | B5: Tipo_o_patron_de_SI | C5: Clasifica el SI como transaccional, ERP, CRM, BPM, CMS, SGD, GIS, solución analítica u otro. | D5: Institucional (Fase 1) | E5: Obligatorio | F5: OTIC + responsables | G5: Lista | H5: Listas!Tipo_o_patron_de_SI | J5: Catálogo
A6: Catálogo_SI | B6: Categoria_institucional | C6: Clasificación institucional misional/estratégica/apoyo/evaluación/otro. | D6: Institucional | E6: Obligatorio | F6: Responsable funcional | G6: Lista | H6: Listas!Categoria_institucional | J6: Catálogo
A7: Catálogo_SI | B7: Descripcion_breve | C7: Resumen de propósito y alcance. | D7: Institucional | E7: Obligatorio | F7: Responsable funcional | G7: Texto corto | H7: No aplica | J7: Catálogo
A8: Catálogo_SI | B8: Procesos_institucionales_soportados | C8: Procesos del mapa institucional soportados por el SI. | D8: MAE / Institucional | E8: Obligatorio | F8: Responsable funcional | G8: Texto / lista | H8: Procesos vigentes | J8: Catálogo
A9: Catálogo_SI | B9: Dependencia_duena_del_proceso | C9: Dependencia dueña del proceso soportado. | D9: Institucional | E9: Obligatorio | F9: Responsable funcional | G9: Lista | H9: Listas!Dependencias_institucionales | J9: Catálogo
A10: Catálogo_SI | B10: Area_responsable_funcional | C10: Área que ejerce liderazgo funcional. | D10: Institucional | E10: Obligatorio | F10: Responsable funcional | G10: Lista | H10: Listas!Dependencias_institucionales | J10: Catálogo
A11: Catálogo_SI | B11: Responsable_funcional | C11: Nombre del responsable funcional designado. | D11: Institucional | E11: Obligatorio | F11: Responsable funcional | G11: Texto | H11: No aplica | J11: Catálogo
A12: Catálogo_SI | B12: Area_responsable_tecnica | C12: Área TI responsable de la operación técnica. | D12: Institucional | E12: Obligatorio | F12: Responsable técnico | G12: Lista | H12: Listas!Dependencias_institucionales | J12: Catálogo
A13: Catálogo_SI | B13: Responsable_tecnico | C13: Nombre del responsable técnico designado. | D13: Institucional | E13: Obligatorio | F13: Responsable técnico | G13: Texto | H13: No aplica | J13: Catálogo
... A30: Catálogo_SI | B30: Interopera_con_entidades_externas | C30: Indica si hay interoperabilidad con terceros externos. | D30: Institucional | E30: Obligatorio | F30: Responsable técnico | G30: Lista | H30: Sí / No | J30: Catálogo
A31: Catálogo_SI | B31: Numero_integraciones_activas | C31: Conteo de integraciones/interfaces vigentes asociadas al SI. | D31: Calculado | E31: Automático | F31: Calculado | G31: Número entero | H31: >=0 | I31: COUNTIFS sobre Integraciones_Interfaces (ID_SI_Origen + Estado=Activa) | J31: Calculado
A32: Catálogo_SI | B32: Numero_componentes_registrados | C32: Conteo de componentes registrados para el SI. | D32: Calculado | E32: Automático | F32: Calculado | G32: Número entero | H32: >=0 | I32: COUNTIF sobre Componentes (ID_SI_Padre) | J32: Calculado
A33: Catálogo_SI | B33: Valoracion_de_seguridad | C33: Vigencia de valoración MSPI/seguridad. | D33: MSPI / institucional | E33: Obligatorio | F33: Técnico / seguridad | G33: Lista | H33: Listas!Valoracion_de_seguridad | J33: Catálogo
A34: Catálogo_SI | B34: Nivel_de_riesgo_residual | C34: Riesgo residual más reciente del SI. | D34: MSPI / institucional | E34: Recomendado | F34: Seguridad / técnico | G34: Lista | H34: Listas!Nivel_de_riesgo_residual | J34: Catálogo
A35: Catálogo_SI | B35: Backup_definido | C35: Indica si existe respaldo definido. | D35: Institucional / continuidad | E35: Obligatorio | F35: Responsable técnico | G35: Lista | H35: Listas!Backup_definido | J35: Catálogo
A36: Catálogo_SI | B36: Plan_de_continuidad | C36: Estado del plan de continuidad/contingencia. | D36: Institucional / MSPI | E36: Recomendado | F36: Responsable técnico | G36: Lista | H36: Listas!Plan_de_continuidad | J36: Catálogo
A37: Catálogo_SI | B37: Estado_documentacion_minima | C37: Resultado agregado del estado de documentación mínima exigible. | D37: MGGTI.G.SI + calculado institucional | E37: Obligatorio | F37: Calculado desde Ficha/Calidad | G37: Lista | H37: Listas!Estado_documentacion_minima | J37: Catálogo
A38: Catálogo_SI | B38: Clasificacion_TIME | C38: Clasificación estratégica final del SI. | D38: Decisión institucional (marco complementario TIME; no obligación MinTIC) | E38: Obligatorio | F38: OTIC / comité | G38: Lista | H38: T, I, M, E | J38: Catálogo
A39: Catálogo_SI | B39: Tipo_intervencion_recomendada | C39: Acción principal sugerida. | D39: Institucional | E39: Obligatorio | F39: OTIC | G39: Lista | H39: Listas!Tipo_intervencion_recomendada | J39: Catálogo
A40: Catálogo_SI | B40: Prioridad_intervencion | C40: Nivel de prioridad resultante. | D40: Institucional / calculado | E40: Obligatorio | F40: OTIC | G40: Lista | H40: Listas!Prioridad_intervencion | J40: Catálogo
A41: Catálogo_SI | B41: TCO_anual_total_COP | C41: Estimado o valor anual consolidado del TCO. | D41: Decisión institucional de gestión del portafolio | E41: Recomendado | F41: Financiero / técnico | G41: Número moneda | H41: >=0 | J41: Catálogo
A42: Catálogo_SI | B42: Ratio_TCO_por_usuario_COP | C42: TCO total dividido por usuarios activos. | D42: Calculado | E42: Recomendado | F42: Calculado | G42: Número moneda | H42: >=0 | I42: TCO_anual_total_COP / Usuarios_activos | J42: Calculado
A43: Catálogo_SI | B43: Ultima_revision_anual | C43: Fecha de última revisión integral del SI. | D43: Institucional | E43: Obligatorio | F43: OTIC | G43: Fecha | H43: DD/MM/AAAA | J43: Catálogo
A44: Catálogo_SI | B44: Proxima_revision_programada | C44: Fecha programada de la próxima revisión. | D44: Institucional | E44: Recomendado | F44: OTIC | G44: Fecha | H44: DD/MM/AAAA | J44: Catálogo
A45: Catálogo_SI | B45: Vigencia_del_registro | C45: Señala si el registro sigue activo o se conserva históricamente. | D45: Institucional | E45: Obligatorio | F45: OTIC / calculado | G45: Lista | H45: Vigente, Histórico | J45: Catálogo
A46: Integraciones_Interfaces | B46: ID_Integracion | C46: Código único de la integración o interfaz (patrón INT-####). | D46: Institucional | E46: Obligatorio | F46: OTIC | G46: Texto | H46: Patrón INT-#### | J46: Catálogo
A47: Integraciones_Interfaces | B47: ID_SI_Origen | C47: ID del SI del catálogo que origina o expone la relación. | D47: Institucional | E47: Obligatorio | F47: Responsable técnico | G47: Texto | H47: Debe existir en Catálogo_SI | J47: Catálogo
A48: Integraciones_Interfaces | B48: Nombre_SI_Origen | C48: Nombre del SI origen (derivado por búsqueda). | D48: Calculado | E48: Automático | F48: Calculado | G48: Texto | I48: VLOOKUP contra Catálogo_SI | J48: Calculado
A49: Integraciones_Interfaces | B49: ID_SI_Destino_o_Activo_Destino | C49: ID del SI destino o identificación del activo/entidad destino. | D49: Institucional | E49: Obligatorio | F49: Responsable técnico | G49: Texto | H49: ID_SI interno o identificador externo | J49: Catálogo
A50: Integraciones_Interfaces | B50: Nombre_Destino | C50: Nombre del sistema, activo o entidad destino. | D50: Institucional | E50: Obligatorio | F50: Responsable técnico | G50: Texto | H50: No aplica | J50: Catálogo
A51: Integraciones_Interfaces | B51: Tipo_de_registro | C51: Naturaleza del registro: integración, interfaz expuesta o consumida. | D51: Institucional | E51: Obligatorio | F51: Responsable técnico | G51: Lista | H51: Listas!Tipo_de_registro | J51: Catálogo
A52: Integraciones_Interfaces | B52: Tipo_de_interfaz_o_mecanismo | C52: Mecanismo técnico de la relación. | D52: Institucional / W3C / OASIS | E52: Obligatorio | F52: Responsable técnico | G52: Lista | H52: Listas!Tipo_de_interfaz_o_mecanismo | J52: Catálogo
A53: Integraciones_Interfaces | B53: Proposito | C53: Objetivo de negocio o técnico del intercambio. | D53: Institucional | E53: Obligatorio | F53: Responsable técnico | G53: Texto corto | H53: No aplica | J53: Catálogo
A54: Integraciones_Interfaces | B54: Direccion_del_flujo | C54: Sentido del flujo de datos respecto del SI origen. | D54: Institucional | E54: Obligatorio | F54: Responsable técnico | G54: Lista | H54: Listas!Direccion_del_flujo | J54: Catálogo
A55: Integraciones_Interfaces | B55: Entidad_externa_relacionada | C55: Entidad externa contraparte cuando aplique. | D55: Institucional | E55: Condicional | F55: Responsable técnico | G55: Texto | H55: Obligatorio si el destino es externo | J55: Catálogo
A56: Integraciones_Interfaces | B56: Criticidad | C56: Impacto de la falla de la integración. | D56: Institucional | E56: Obligatorio | F56: Responsable técnico | G56: Lista | H56: Alta, Media, Baja | J56: Catálogo
...

Sheet Listas
A1: Tipo_o_patron_de_SI | B1: Categoria_institucional | C1: Estado_del_SI | D1: Modelo_de_despliegue | E1: Tipo_de_desarrollo_adquisicion | F1: Tipo_de_licenciamiento | G1: Estado_ANS_terceros | H1: Criticidad_operacional | I1: Cobertura_del_proceso | J1: Clasificacion_de_la_informacion | K1: Manejo_de_datos_personales | L1: Si_No | M1: Backup_definido | N1: Valoracion_de_seguridad | O1: Nivel_de_riesgo_residual | P1: Plan_de_continuidad | Q1: Estado_documentacion_minima | R1: Clasificacion_TIME | S1: Tipo_intervencion_recomendada | T1: Prioridad_intervencion | U1: Vigencia_del_registro | V1: Dependencias_institucionales | W1: Tipo_de_registro | X1: Tipo_de_interfaz_o_mecanismo | Y1: Direccion_del_flujo | Z1: Frecuencia | AA1: Estado_Integracion_Componente | AB1: Criticidad | AC1: Tipo_de_Componente | AD1: Tipo_de_hallazgo | AE1: Estado_hallazgo
A2: Sistema transaccional | B2: Misional | C2: Activo | D2: On-premises | E2: Propio | F2: Perpetuo | G2: Vigente | H2: Alta | I2: Alto | J2: Pública | K2: Sí - responsable | L2: Sí | M2: Sí | N2: Vigente | O2: Alto | P2: Vigente | Q2: Completa | R2: T | S2: Modernizar | T2: Alta | U2: Vigente | V2: (Diligenciar con el listado oficial de dependencias del Ministerio) | W2: Integración | X2: API REST | Y2: Entrada | Z2: Tiempo real | AA2: Activa | AB2: Alta | AC2: Módulo funcional | AD2: Completitud | AE2: Abierto
A3: ERP | B3: Estratégica | C3: En desarrollo | D3: Nube pública | E3: A la medida | F3: Suscripción | G3: Vencido | H3: Media | I3: Medio | J3: Uso interno | K3: Sí - encargado | L3: No | M3: No | N3: Desactualizada | O3: Medio | P3: Desactualizado | Q3: Parcial | R3: I | S3: Migrar | T3: Media | U3: Histórico | W3: Interfaz expuesta | X3: API SOAP / servicio web | Y3: Salida | Z3: Diaria | AA3: Inactiva | AB3: Media | AC3: Microservicio | AD3: Vocabulario | AE3: En curso
A4: CRM | B4: Apoyo | C4: En mantenimiento | D4: Nube privada | E4: COTS | F4: Open source | G4: En negociación | H4: Baja | I4: Bajo | J4: Reservada | K4: No | M4: Desconocido | N4: No realizada | O4: Bajo | P4: No existe | Q4: Crítica | R4: M | S4: Retirar | T4: Baja | W4: Interfaz consumida | X4: Archivo plano | Y4: Bidireccional | Z4: Semanal | AA4: En construcción | AB4: Baja | AC4: API interna | AD4: Consistencia entre hojas | AE4: Cerrado
A5: BPM / BPMS | B5: Evaluación y control | C5: En migración | D5: Híbrida | E5: Open source | F5: Incluido en servicio | G5: No aplica | I5: No evaluado | J5: Clasificada | O5: No evaluado | Q5: No evaluada | R5: E | S5: Sostener | X5: Conexión a base de datos | Z5: Mensual | AA5: Retirada | AC5: Servicio web | AD5: Vigencia (soporte/seguridad/continuidad)
A6: CMS | B6: Otro | C6: Deprecado | D6: SaaS | E6: SaaS | F6: Sin licenciamiento | S6: Optimizar | X6: Mensajería / cola | Z6: Por demanda | AC6: Base de datos | AD6: Migración
A7: Sistema de Gestión Documental | C7: Retirado | D7: PaaS | E7: Híbrido | F7: Otro | X7: ETL | Z7: Otra | AC7: Batch / job programado | AD7: Otro
A8: GIS | E8: Legado | X8: Bus de integración / iPaaS | AC8: Portal / frontend
A9: Solución analítica | X9: Otro | AC9: Middleware
A10: Otro SI institucional | AC10: Otro

Sheet Tablero
A1: TABLERO GERENCIAL — F-A-GTI-02 Catálogo Institucional de Sistemas de Información
A3: 1. Tamaño del portafolio
A4: SI vigentes | B4: =COUNTIF('Catálogo_SI'!$AR:$AR,"Vigente")
A5: SI históricos | B5: =COUNTIF('Catálogo_SI'!$AR:$AR,"Histórico")
A6: Total de registros | B6: =COUNTA('Catálogo_SI'!$A:$A)-1
A8: 2. SI por tipo o patrón
A9: Sistema transaccional | B9: =COUNTIF('Catálogo_SI'!$D:$D,"Sistema transaccional")
A10: ERP | B10: =COUNTIF('Catálogo_SI'!$D:$D,"ERP")
A11: CRM | B11: =COUNTIF('Catálogo_SI'!$D:$D,"CRM")
A12: BPM / BPMS | B12: =COUNTIF('Catálogo_SI'!$D:$D,"BPM / BPMS")
A13: CMS | B13: =COUNTIF('Catálogo_SI'!$D:$D,"CMS")
A14: Sistema de Gestión Documental | B14: =COUNTIF('Catálogo_SI'!$D:$D,"Sistema de Gestión Documental")
A15: GIS | B15: =COUNTIF('Catálogo_SI'!$D:$D,"GIS")
A16: Solución analítica | B16: =COUNTIF('Catálogo_SI'!$D:$D,"Solución analítica")
A17: Otro SI institucional | B17: =COUNTIF('Catálogo_SI'!$D:$D,"Otro SI institucional")
A19: 3. SI por categoría institucional
A20: Misional | B20: =COUNTIF('Catálogo_SI'!$E:$E,"Misional")
A21: Estratégica | B21: =COUNTIF('Catálogo_SI'!$E:$E,"Estratégica")
A22: Apoyo | B22: =COUNTIF('Catálogo_SI'!$E:$E,"Apoyo")
A23: Evaluación y control | B23: =COUNTIF('Catálogo_SI'!$E:$E,"Evaluación y control")
A24: Otro | B24: =COUNTIF('Catálogo_SI'!$E:$E,"Otro")
A26: 4. TIME del portafolio (marco complementario institucional)
A27: Tolerate — Tolerar | B27: =COUNTIF('Catálogo_SI'!$AK:$AK,"T")
A28: Invest — Invertir | B28: =COUNTIF('Catálogo_SI'!$AK:$AK,"I")
A29: Migrate — Migrar | B29: =COUNTIF('Catálogo_SI'!$AK:$AK,"M")
A30: Eliminate — Eliminar | B30: =COUNTIF('Catálogo_SI'!$AK:$AK,"E")
A32: 5. Alertas de soporte
A33: SI con soporte vencido | B33: =COUNTIFS('Catálogo_SI'!$T:$T,"<"&TODAY(),'Catálogo_SI'!$T:$T,"<>")
A34: SI con soporte por vencer (90 días) | B34: =COUNTIFS('Catálogo_SI'!$T:$T,">="&TODAY(),'Catálogo_SI'!$T:$T,"<="&TODAY()+90)
A36: 6. Dimensión económica
A37: TCO total anual del portafolio (COP) | B37: =SUM('Catálogo_SI'!$AN:$AN)
A38: TCO promedio por SI (COP) | B38: =IFERROR(ROUND(AVERAGE('Catálogo_SI'!$AN:$AN),0),0)
A40: 7. Alertas de seguridad, continuidad y documentación
A41: SI con valoración de seguridad desactualizada | B41: =COUNTIF('Catálogo_SI'!$AF:$AF,"Desactualizada")
A42: SI sin valoración de seguridad realizada | B42: =COUNTIF('Catálogo_SI'!$AF:$AF,"No realizada")
A43: SI sin plan de continuidad vigente | B43: =COUNTIF('Catálogo_SI'!$AI:$AI,"Desactualizado")+COUNTIF('Catálogo_SI'!$AI:$AI,"No existe")
A44: SI con documentación crítica | B44: =COUNTIF('Catálogo_SI'!$AJ:$AJ,"Crítica")
A45: SI sin backup definido o desconocido | B45: =COUNTIF('Catálogo_SI'!$AH:$AH,"No")+COUNTIF('Catálogo_SI'!$AH:$AH,"Desconocido")
A47: 8. Revisiones
A48: Revisiones programadas próximos 90 días | B48: =COUNTIFS('Catálogo_SI'!$AQ:$AQ,">="&TODAY(),'Catálogo_SI'!$AQ:$AQ,"<="&TODAY()+90)
...

Sheet Calidad
A1: A. Completitud del registro por SI (calculada) | E1: B. Hallazgos, inconsistencias y trazabilidad de migración
A2: ID_SI | B2: Nombre_oficial | C2: Completitud del registro (44 campos) | E2: ID_Hallazgo | F2: ID_SI | G2: Tipo_de_hallazgo | H2: Campo(s) afectado(s) | I2: Descripción del hallazgo | J2: Fecha_deteccion | K2: Responsable_correccion | L2: Estado_hallazgo | M2: Fecha_cierre | N2: Observaciones (incluye trazabilidad de reclasificación / migración)
A3: ='Catálogo_SI'!A2 | B3: =IF('Catálogo_SI'!A2="","",'Catálogo_SI'!B2) | C3: =IF('Catálogo_SI'!A2="","",ROUND(COUNTA('Catálogo_SI'!A2:AR2)/44,2))
A4: ='Catálogo_SI'!A3 | B4: =IF('Catálogo_SI'!A3="","",'Catálogo_SI'!B3) | C4: =IF('Catálogo_SI'!A3="","",ROUND(COUNTA('Catálogo_SI'!A3:AR3)/44,2))
A5: ='Catálogo_SI'!A4 | B5: =IF('Catálogo_SI'!A4="","",'Catálogo_SI'!B4) | C5: =IF('Catálogo_SI'!A4="","",ROUND(COUNTA('Catálogo_SI'!A4:AR4)/44,2))
A6: ='Catálogo_SI'!A5 | B6: =IF('Catálogo_SI'!A5="","",'Catálogo_SI'!B5) | C6: =IF('Catálogo_SI'!A5="","",ROUND(COUNTA('Catálogo_SI'!A5:AR5)/44,2))
A7: ='Catálogo_SI'!A6 | B7: =IF('Catálogo_SI'!A6="","",'Catálogo_SI'!B6) | C7: =IF('Catálogo_SI'!A6="","",ROUND(COUNTA('Catálogo_SI'!A6:AR6)/44,2))
A8: ='Catálogo_SI'!A7 | B8: =IF('Catálogo_SI'!A7="","",'Catálogo_SI'!B7) | C8: =IF('Catálogo_SI'!A7="","",ROUND(COUNTA('Catálogo_SI'!A7:AR7)/44,2))
A9: ='Catálogo_SI'!A8 | B9: =IF('Catálogo_SI'!A8="","",'Catálogo_SI'!B8) | C9: =IF('Catálogo_SI'!A8="","",ROUND(COUNTA('Catálogo_SI'!A8:AR8)/44,2))
A10: ='Catálogo_SI'!A9 | B10: =IF('Catálogo_SI'!A9="","",'Catálogo_SI'!B9) | C10: =IF('Catálogo_SI'!A9="","",ROUND(COUNTA('Catálogo_SI'!A9:AR9)/44,2))
A11: ='Catálogo_SI'!A10 | B11: =IF('Catálogo_SI'!A10="","",'Catálogo_SI'!B10) | C11: =IF('Catálogo_SI'!A10="","",ROUND(COUNTA('Catálogo_SI'!A10:AR10)/44,2))
A12: ='Catálogo_SI'!A11 | B12: =IF('Catálogo_SI'!A11="","",'Catálogo_SI'!B11) | C12: =IF('Catálogo_SI'!A11="","",ROUND(COUNTA('Catálogo_SI'!A11:AR11)/44,2))
A13: ='Catálogo_SI'!A12 | B13: =IF('Catálogo_SI'!A12="","",'Catálogo_SI'!B12) | C13: =IF('Catálogo_SI'!A12="","",ROUND(COUNTA('Catálogo_SI'!A12:AR12)/44,2))
A14: ='Catálogo_SI'!A13 | B14: =IF('Catálogo_SI'!A13="","",'Catálogo_SI'!B13) | C14: =IF('Catálogo_SI'!A13="","",ROUND(COUNTA('Catálogo_SI'!A13:AR13)/44,2))
... A502: ='Catálogo_SI'!A501 | B502: =IF('Catálogo_SI'!A501="","",'Catálogo_SI'!B501) | C502: =IF('Catálogo_SI'!A501="","",ROUND(COUNTA('Catálogo_SI'!A501:AR501)/44,2))
